const main = async () => {
  await Promise.resolve();
};

main().catch((err) => {
  throw err;
});
